{"uuid": "98e87cfb-d6d2-49f7-85b4-d4c6c88e204e", "children": ["21016c94-1789-4e6f-83f4-0ea711f995ea", "1a96b665-15b5-487c-bebf-5d3f63057c85", "d5642a57-48a1-49b0-a0e3-9588d04582db", "0f79bec7-0336-42fa-9f93-04446bb516db"], "befores": [{"name": "_Class__pytest_setup_class", "status": "broken", "statusDetails": {"message": "selenium.common.exceptions.WebDriverException: Message: An unknown server-side error occurred while processing the command. Original error: Error occured while starting App. Original error: Activity used to start app doesn't exist or cannot be launched! Make sure it exists and is a launchable activity\n\n", "trace": "  File \"d:\\program files\\python37\\lib\\site-packages\\pluggy\\callers.py\", line 187, in _multicall\n    res = hook_impl.function(*args)\n  File \"d:\\program files\\python37\\lib\\site-packages\\_pytest\\fixtures.py\", line 964, in pytest_fixture_setup\n    result = call_fixture_func(fixturefunc, request, kwargs)\n  File \"d:\\program files\\python37\\lib\\site-packages\\_pytest\\fixtures.py\", line 788, in call_fixture_func\n    res = next(it)\n  File \"d:\\program files\\python37\\lib\\site-packages\\_pytest\\python.py\", line 701, in xunit_setup_class_fixture\n    _call_with_optional_argument(func, self.obj)\n  File \"d:\\program files\\python37\\lib\\site-packages\\_pytest\\python.py\", line 632, in _call_with_optional_argument\n    func(arg)\n  File \"D:\\python\\Rep\\scripts\\test_add_user.py\", line 22, in setup_class\n    self.driver = init_driver()\n  File \"D:\\python\\Rep\\Base\\InitDiver.py\", line 19, in init_driver\n    driver = webdriver.Remote('http://127.0.0.1:4723/wd/hub', desired_caps)\n  File \"d:\\program files\\python37\\lib\\site-packages\\appium_python_client-0.25-py3.7.egg\\appium\\webdriver\\webdriver.py\", line 36, in __init__\n    super(WebDriver, self).__init__(command_executor, desired_capabilities, browser_profile, proxy, keep_alive)\n  File \"d:\\program files\\python37\\lib\\site-packages\\selenium\\webdriver\\remote\\webdriver.py\", line 157, in __init__\n    self.start_session(capabilities, browser_profile)\n  File \"d:\\program files\\python37\\lib\\site-packages\\selenium\\webdriver\\remote\\webdriver.py\", line 252, in start_session\n    response = self.execute(Command.NEW_SESSION, parameters)\n  File \"d:\\program files\\python37\\lib\\site-packages\\selenium\\webdriver\\remote\\webdriver.py\", line 321, in execute\n    self.error_handler.check_response(response)\n  File \"d:\\program files\\python37\\lib\\site-packages\\selenium\\webdriver\\remote\\errorhandler.py\", line 242, in check_response\n    raise exception_class(message, screen, stacktrace)\n"}, "start": 1593938166265, "stop": 1593938178619}], "start": 1593938166265, "stop": 1593938179029}