{"uuid": "1fc5fce9-48b7-4eed-88c8-40fe1b275b3f", "children": ["80e70e30-78e5-4ae9-a332-85147da2f84f", "38850622-7386-4e36-b049-671ddd06882a", "cfe94b11-67f6-4e1a-8f92-0b999041dd63", "bb93b46a-b2c8-4ce0-bb00-ee373cea8e86"], "befores": [{"name": "_Class__pytest_setup_class", "status": "broken", "statusDetails": {"message": "selenium.common.exceptions.WebDriverException: Message: An unknown server-side error occurred while processing the command. Original error: Error occured while starting App. Original error: Activity used to start app doesn't exist or cannot be launched! Make sure it exists and is a launchable activity\n\n", "trace": "  File \"d:\\program files\\python37\\lib\\site-packages\\pluggy\\callers.py\", line 187, in _multicall\n    res = hook_impl.function(*args)\n  File \"d:\\program files\\python37\\lib\\site-packages\\_pytest\\fixtures.py\", line 964, in pytest_fixture_setup\n    result = call_fixture_func(fixturefunc, request, kwargs)\n  File \"d:\\program files\\python37\\lib\\site-packages\\_pytest\\fixtures.py\", line 788, in call_fixture_func\n    res = next(it)\n  File \"d:\\program files\\python37\\lib\\site-packages\\_pytest\\python.py\", line 701, in xunit_setup_class_fixture\n    _call_with_optional_argument(func, self.obj)\n  File \"d:\\program files\\python37\\lib\\site-packages\\_pytest\\python.py\", line 632, in _call_with_optional_argument\n    func(arg)\n  File \"D:\\python\\Rep\\scripts\\test_add_user.py\", line 22, in setup_class\n    self.driver = init_driver()\n  File \"D:\\python\\Rep\\Base\\InitDiver.py\", line 19, in init_driver\n    driver = webdriver.Remote('http://127.0.0.1:4723/wd/hub', desired_caps)\n  File \"d:\\program files\\python37\\lib\\site-packages\\appium_python_client-0.25-py3.7.egg\\appium\\webdriver\\webdriver.py\", line 36, in __init__\n    super(WebDriver, self).__init__(command_executor, desired_capabilities, browser_profile, proxy, keep_alive)\n  File \"d:\\program files\\python37\\lib\\site-packages\\selenium\\webdriver\\remote\\webdriver.py\", line 157, in __init__\n    self.start_session(capabilities, browser_profile)\n  File \"d:\\program files\\python37\\lib\\site-packages\\selenium\\webdriver\\remote\\webdriver.py\", line 252, in start_session\n    response = self.execute(Command.NEW_SESSION, parameters)\n  File \"d:\\program files\\python37\\lib\\site-packages\\selenium\\webdriver\\remote\\webdriver.py\", line 321, in execute\n    self.error_handler.check_response(response)\n  File \"d:\\program files\\python37\\lib\\site-packages\\selenium\\webdriver\\remote\\errorhandler.py\", line 242, in check_response\n    raise exception_class(message, screen, stacktrace)\n"}, "start": 1593939050505, "stop": 1593939061542}], "start": 1593939050505, "stop": 1593939061928}